<?xml version="1.0" encoding="UTF-8"?>
<robot name="valvula">
  <joint name="RevoluteJoint" type="revolute">
    <origin xyz="0.0373985 0. 0. " rpy="0. 0. 3.14159"/>
    <parent link="body"/>
    <child link="lever_pivot"/>
    <axis xyz="1. 0. 0."/>
    <limit lower="0." upper="1.5707963" effort="100." velocity="10."/>
  </joint>
  <link name="body">
<inertial>
      <origin xyz="0 0 0" rpy="0 0 0"/>
      <mass value="1.0"/>
      <inertia ixx="0.001" ixy="0" ixz="0" iyy="0.001" iyz="0" izz="0.001"/>
    </inertial>  
    <visual>
      <origin xyz="0.0374 0. 0. " rpy="0. 0. 1.5707964"/>
      <geometry>
        <mesh filename="./meshes/Mesh_1.obj" scale="1. 1. 1."/>
      </geometry>
    </visual>
    <collision>
      <origin xyz="0.04 0.01150000054622069 -1.5075335787680833e-19" rpy="0 0 0"/>
      <geometry>
        <box size="0.06400000303983688 0.06000000284984708 0.0370000017574057"/>
      </geometry>
    </collision>
  </link>
  <link name="lever_pivot">
<inertial>
      <origin xyz="0 0 0" rpy="0 0 0"/>
      <mass value="0.2"/>
      <inertia ixx="0.0001" ixy="0" ixz="0" iyy="0.0001" iyz="0" izz="0.0001"/>
    </inertial>  
    <visual>
    <origin xyz="0. -0.0000015 0. " rpy="0. 0. -1.5707963"/>
      <geometry>
        <mesh filename="./meshes/Mesh_3.obj" scale="1. 1. 1."/>
      </geometry>
    </visual>
    <collision>
    <origin xyz="0.038 0.039 0.0019985137935021884" rpy="0 0 -1.5707963"/>      <geometry>
        <box size="0.10550000119628367 0.029 0.019"/>
      </geometry>
    </collision>
  </link>
</robot>
