<?xml version="1.0" ?>
<robot name="spot_with_arm">

  <!-- ####################### Body ####################### -->
  <link name="body">
    <collision>
      <geometry>
        <mesh filename="meshes/base/collision/body_collision.obj"/>
      </geometry>
    </collision>
    <collision>
      <geometry>
        <box size= "0.045 0.18 0.18"/>
      </geometry>
      <origin rpy="0.0 0.4 0.0" xyz="0.40 0.0 -0.022"/>
    </collision>
    <collision>
      <geometry>
        <box size= "0.065 0.16 0.145"/>
      </geometry>
      <origin rpy="0.0 0.0 0.0" xyz="-0.40 0.0 0.0"/>
    </collision>
    <visual>
      <geometry>
        <mesh filename="meshes/base/visual/body.obj"/>
      </geometry>
    </visual>
    <inertial>
      <origin xyz="0 0 -0.00496172"/>
      <mass value="16.70765207"/>
      <inertia ixx="0.081543792" ixy="0.0" ixz="0.0" iyy="0.549231154" iyz="0.0" izz="0.569454373"/>
    </inertial>
  </link>

  <!-- Front Left Hip Link -->
  <link name="fl_hip">
    <visual>
      <geometry>
        <mesh filename="meshes/base/visual/front_left_hip.obj"/>
      </geometry>
    </visual>
    <inertial>
      <origin xyz="-0.01586739 0.00855842 0.00000903"/>
      <inertia ixx="0.00122166" ixy="-0.00017754" ixz="0.00000043" iyy="0.00158957" iyz="-0.00000049" izz="0.00172903"/>
      <mass value="1.13688339"/>
    </inertial>
  </link>

  <joint name="fl_hx" type="revolute">
    <origin rpy="0 0 0" xyz="0.29785 0.05500 0.00000"/>
    <axis xyz="1 0 0"/>
    <parent link="body"/>
    <child link="fl_hip"/>
    <limit effort="45" lower="-0.785398" upper="0.785398" velocity="100"/>
  </joint>

  <!-- Front Left Upper Leg -->
  <link name="fl_uleg">
    <visual>
      <geometry>
        <mesh filename="meshes/base/visual/front_left_upper_leg.obj"/>
      </geometry>
    </visual>
    <collision>
      <geometry>
         <mesh filename="meshes/base/collision/upper_leg_collision.obj"/>
      </geometry>
    </collision>
    <inertial>
      <origin xyz="0.00214442 -0.01110184 -0.07881204"/>
      <inertia ixx="0.02692501" ixy="-0.00008782" ixz="0.00054873" iyy="0.02583907" iyz="0.00207146" izz="0.00318737"/>
      <mass value="2.25620359"/>
    </inertial>
  </link>

  <joint name="fl_hy" type="revolute">
    <origin rpy="0 0 0" xyz="0.0 0.110945 0.0"/>
    <axis xyz="0 1 0"/>
    <parent link="fl_hip"/>
    <child link="fl_uleg"/>
    <limit effort="45" lower="-0.898845" upper="2.295108" velocity="100"/>
  </joint>

  <!-- Front Left Lower Leg -->
  <link name="fl_lleg">
    <visual>
      <geometry>
        <mesh filename="meshes/base/visual/front_left_lower_leg.obj"/>
      </geometry>
   </visual>
    <collision>
      <geometry>
         <mesh filename="meshes/base/collision/lower_leg_collision.obj"/>
      </geometry>
    </collision>
    <inertial>
      <origin xyz="0.00597360 0.0 -0.17466427"/>
      <inertia ixx="0.00701356" ixy="0.0" ixz="0.00006600" iyy="0.00709946" iyz="0.0" izz="0.00014529"/>
      <mass value="0.330"/>
    </inertial>
  </link>

  <joint name="fl_kn" type="revolute">
    <origin rpy="0 0 0" xyz="0.025 0.000 -0.3205"/>
    <axis xyz="0 1 0"/>
    <parent link="fl_uleg"/>
    <child link="fl_lleg"/>
    <limit effort="115" lower="-2.7929" upper="-0.2471" velocity="100"/>
  </joint>

  <!-- Front Left Foot -->
  <link name="fl_foot">
    <collision>
      <geometry>
        <sphere radius="0.036"/>
      </geometry>
    </collision>
  </link>

  <joint name="fl_ank" type="fixed">
    <origin xyz="0.0 0.0 -0.3365"/>
    <parent link="fl_lleg"/>
    <child link="fl_foot"/>
  </joint>

  <!-- Front Right Hip -->
  <link name="fr_hip">
    <visual>
      <geometry>
        <mesh filename="meshes/base/visual/front_right_hip.obj"/>
      </geometry>
   </visual>
    <inertial>
      <origin xyz="-0.01586739 -0.00855842 0.00000903"/>
      <inertia ixx="0.00122166" ixy="0.00017754" ixz="0.00000043" iyy="0.00158957" iyz="0.00000049" izz="0.00172903"/>
      <mass value="1.13688339"/>
    </inertial>
  </link>

  <joint name="fr_hx" type="revolute">
    <origin rpy="0 0 0" xyz="0.29785 -0.05500 0.00000"/>
    <axis xyz="1 0 0"/>
    <parent link="body"/>
    <child link="fr_hip"/>
    <limit effort="45" lower="-0.785398" upper="0.785398" velocity="100"/>
  </joint>

  <!-- Front Right Upper Leg -->
  <link name="fr_uleg">
    <visual>
      <geometry>
        <mesh filename="meshes/base/visual/front_right_upper_leg.obj"/>
      </geometry>
   </visual>
     <collision>
      <geometry>
         <mesh filename="meshes/base/collision/upper_leg_collision.obj"/>
      </geometry>
      <origin rpy="0.0 0.0 3.14159265359" xyz="0.0 0.0 0.0"/>
    </collision>
    <inertial>
      <origin xyz="0.00214442 0.01110184 -0.07881204"/>
      <inertia ixx="0.02692501" ixy="0.00008782" ixz="0.00054873" iyy="0.02583907" iyz="-0.00207146" izz="0.00318737"/>
      <mass value="2.25620359"/>
    </inertial>
  </link>

  <joint name="fr_hy" type="revolute">
    <origin rpy="0 0 0" xyz="0.0 -0.110945 0.0"/>
    <axis xyz="0 1 0"/>
    <parent link="fr_hip"/>
    <child link="fr_uleg"/>
    <limit effort="45" lower="-0.898845" upper="2.295108" velocity="100"/>
  </joint>

  <!-- Front Right Lower Leg -->
  <link name="fr_lleg">
    <visual>
      <geometry>
        <mesh filename="meshes/base/visual/front_right_lower_leg.obj"/>
      </geometry>
   </visual>
    <collision>
      <geometry>
         <mesh filename="meshes/base/collision/lower_leg_collision.obj"/>
      </geometry>
    </collision>
    <inertial>
      <origin xyz="0.00597360 0.0 -0.17466427"/>
      <inertia ixx="0.00701356" ixy="0.0" ixz="0.00006600" iyy="0.00709946" iyz="0.0" izz="0.00014529"/>
      <mass value="0.330"/>
    </inertial>
  </link>

  <joint name="fr_kn" type="revolute">
    <origin rpy="0 0 0" xyz="0.025 0.000 -0.3205"/>
    <axis xyz="0 1 0"/>
    <parent link="fr_uleg"/>
    <child link="fr_lleg"/>
    <limit effort="115" lower="-2.7929" upper="-0.2471" velocity="100"/>
  </joint>

  <!-- Front Right Foot -->
  <link name="fr_foot">
    <collision>
      <geometry>
        <sphere radius="0.036"/>
      </geometry>
    </collision>
  </link>

  <joint name="fr_ank" type="fixed">
    <origin xyz="0.0 0.0 -0.3365"/>
    <parent link="fr_lleg"/>
    <child link="fr_foot"/>
  </joint>

  <!-- Hind Left Hip -->
  <link name="hl_hip">
    <visual>
      <geometry>
        <mesh filename="meshes/base/visual/rear_left_hip.obj"/>
      </geometry>
   </visual>
    <inertial>
      <origin xyz="0.01586739 0.00855842 0.00000903"/>
      <inertia ixx="0.00122166" ixy="0.00017754" ixz="-0.00000043" iyy="0.00158957" iyz="-0.00000049" izz="0.00172903"/>
      <mass value="1.13688339"/>
    </inertial>
  </link>

  <joint name="hl_hx" type="revolute">
    <origin rpy="0 0 0" xyz="-0.29785 0.05500 0.00000"/>
    <axis xyz="1 0 0"/>
    <parent link="body"/>
    <child link="hl_hip"/>
    <limit effort="45" lower="-0.785398" upper="0.785398" velocity="100"/>
  </joint>

  <!-- Hind Left Upper Leg -->
  <link name="hl_uleg">
    <visual>
      <geometry>
         <mesh filename="meshes/base/visual/rear_left_upper_leg.obj"/>
      </geometry>
   </visual>
    <collision>
      <geometry>
         <mesh filename="meshes/base/collision/upper_leg_collision.obj"/>
      </geometry>
    </collision>
    <inertial>
      <origin xyz="0.00214442 -0.01110184 -0.07881204"/>
      <inertia ixx="0.02692501" ixy="-0.00008782" ixz="0.00054873" iyy="0.02583907" iyz="0.00207146" izz="0.00318737"/>
      <mass value="2.25620359"/>
    </inertial>
  </link>

  <joint name="hl_hy" type="revolute">
    <origin rpy="0 0 0" xyz="0.0 0.110945 0.0"/>
    <axis xyz="0 1 0"/>
    <parent link="hl_hip"/>
    <child link="hl_uleg"/>
    <limit effort="45" lower="-0.898845" upper="2.295108" velocity="100"/>
  </joint>

  <!-- Hind Left Lower Leg -->
  <link name="hl_lleg">
    <visual>
      <geometry>
         <mesh filename="meshes/base/visual/rear_left_lower_leg.obj"/>
      </geometry>
   </visual>
    <collision>
      <geometry>
         <mesh filename="meshes/base/collision/lower_leg_collision.obj"/>
      </geometry>
    </collision>
    <inertial>
      <origin xyz="0.00597360 0.0 -0.17466427"/>
      <inertia ixx="0.00701356" ixy="0.0" ixz="0.00006600" iyy="0.00709946" iyz="0.0" izz="0.00014529"/>
      <mass value="0.330"/>
    </inertial>
  </link>

  <joint name="hl_kn" type="revolute">
    <origin rpy="0 0 0" xyz="0.025 0.000 -0.3205"/>
    <axis xyz="0 1 0"/>
    <parent link="hl_uleg"/>
    <child link="hl_lleg"/>
    <limit effort="115" lower="-2.7929" upper="-0.2471" velocity="100"/>
  </joint>

  <!-- Hind Left Foot -->
  <link name="hl_foot">
    <collision>
      <geometry>
        <sphere radius="0.036"/>
      </geometry>
    </collision>
  </link>

  <joint name="hl_ank" type="fixed">
    <origin xyz="0.0 0.0 -0.3365"/>
    <parent link="hl_lleg"/>
    <child link="hl_foot"/>
  </joint>

  <!-- Hind Right Hip -->
  <link name="hr_hip">
    <visual>
      <geometry>
        <mesh filename="meshes/base/visual/rear_right_hip.obj"/>
      </geometry>
   </visual>
    <inertial>
      <origin xyz="0.01586739 -0.00855842 0.00000903"/>
      <inertia ixx="0.00122166" ixy="-0.00017754" ixz="-0.00000043" iyy="0.00158957" iyz="0.00000049" izz="0.00172903"/>
      <mass value="1.13688339"/>
    </inertial>
  </link>

  <joint name="hr_hx" type="revolute">
    <origin rpy="0 0 0" xyz="-0.29785 -0.05500 0.00000"/>
    <axis xyz="1 0 0"/>
    <parent link="body"/>
    <child link="hr_hip"/>
    <limit effort="45" lower="-0.785398" upper="0.785398" velocity="100"/>
  </joint>

  <!-- Hind Right Upper Leg -->
  <link name="hr_uleg">
    <visual>
      <geometry>
         <mesh filename="meshes/base/visual/rear_right_upper_leg.obj"/>
      </geometry>
   </visual>
     <collision>
      <geometry>
         <mesh filename="meshes/base/collision/upper_leg_collision.obj"/>
      </geometry>
      <origin rpy="0.0 0.0 3.14159265359" xyz="0.0 0.0 0.0"/>
    </collision>
    <inertial>
      <origin xyz="0.00214442 0.01110184 -0.07881204"/>
      <inertia ixx="0.02692501" ixy="0.00008782" ixz="0.00054873" iyy="0.02583907" iyz="-0.00207146" izz="0.00318737"/>
      <mass value="2.25620359"/>
    </inertial>
  </link>

  <joint name="hr_hy" type="revolute">
    <origin rpy="0 0 0" xyz="0.0 -0.110945 0.0"/>
    <axis xyz="0 1 0"/>
    <parent link="hr_hip"/>
    <child link="hr_uleg"/>
    <limit effort="45" lower="-0.898845" upper="2.295108" velocity="100"/>
  </joint>

  <!-- Hind Right Lower Leg -->
  <link name="hr_lleg">
    <visual>
      <geometry>
        <mesh filename="meshes/base/visual/rear_right_lower_leg.obj"/>
      </geometry>
   </visual>
    <collision>
      <geometry>
         <mesh filename="meshes/base/collision/lower_leg_collision.obj"/>
      </geometry>
    </collision>
    <inertial>
      <origin xyz="0.00597360 0.0 -0.17466427"/>
      <inertia ixx="0.00701356" ixy="0.0" ixz="0.00006600" iyy="0.00709946" iyz="0.0" izz="0.00014529"/>
      <mass value="0.330"/>
    </inertial>
  </link>

  <joint name="hr_kn" type="revolute">
    <origin rpy="0 0 0" xyz="0.025 0.000 -0.3205"/>
    <axis xyz="0 1 0"/>
    <parent link="hr_uleg"/>
    <child link="hr_lleg"/>
    <limit effort="115" lower="-2.7929" upper="-0.2471" velocity="100"/>
  </joint>

  <!-- Hind Right Foot -->
  <link name="hr_foot">
    <collision>
      <geometry>
        <sphere radius="0.036"/>
      </geometry>
    </collision>
  </link>

  <joint name="hr_ank" type="fixed">
    <origin xyz="0.0 0.0 -0.3365"/>
    <parent link="hr_lleg"/>
    <child link="hr_foot"/>
  </joint>

  <!-- ####################### Arm ####################### -->
  <link name="arm_link_sh0">
    <visual>
      <origin xyz="0 0 0" rpy="0 0 0"/>
      <geometry>
        <mesh filename="meshes/arm/visual/arm_link_sh0.obj"/>
      </geometry>
    </visual>
    <!-- <collision>
      <geometry>
        <mesh filename="meshes/arm/collision/arm_link_sh0_base.obj" />
      </geometry>
    </collision>
    <collision>
      <geometry>
        <mesh filename="meshes/arm/collision/arm_link_sh0_left_motor.obj" />
      </geometry>
    </collision>
     <collision>
      <geometry>
        <mesh filename="meshes/arm/collision/arm_link_sh0_right_motor.obj" />
      </geometry>
    </collision> -->
    <inertial>
      <origin xyz="-0.008399 0.000272 -0.024603"/>
      <inertia ixx="0.008896" ixy="0.000005" ixz="-0.000193" iyy="0.004922" iyz="0.000033" izz="0.0073030"/>
      <mass value="1.904699"/>
    </inertial>
  </link>

  <joint name="arm_sh0" type="revolute">
    <origin xyz="0.292 0.0 0.188" rpy="0 0 0"/>
    <axis xyz="0 0 1"/>
    <parent link="body"/>
    <child link="arm_link_sh0"/>
    <limit effort="90.9" lower="-2.61799" upper="3.14159" velocity="100"/>
  </joint>

  <link name="arm_link_sh1">
    <visual>
      <origin xyz="0 0 0" rpy="0 0 0"/>
      <geometry>
        <mesh filename="meshes/arm/visual/arm_link_sh1.obj"/>
      </geometry>
    </visual>
    <!-- collision disabled for loco self-collision (arm is cuRobo-driven, off-distribution) -->
    <!-- <collision>
      <geometry>
        <mesh filename="meshes/arm/collision/arm_link_sh1.obj" />
      </geometry>
    </collision> -->
    <inertial>
      <origin xyz="0.08084909 -0.00167243 0.00045644"/>
      <inertia ixx="0.00261526" ixy="-0.00040406" ixz="0.00010019" iyy="0.02703868" iyz="0.00000547" izz="0.02819929"/>
      <mass value="1.85701942"/>
    </inertial>
  </link>

  <joint name="arm_sh1" type="revolute">
    <origin xyz="0.0 0.0 0.0" rpy="0 0 0"/>
    <axis xyz="0 1 0"/>
    <parent link="arm_link_sh0"/>
    <child link="arm_link_sh1"/>
    <limit effort="181.8" lower="-3.14159" upper="0.523599" velocity="100"/>
  </joint>

  <link name="arm_link_el0">
    <visual>
      <origin xyz="0 0 0" rpy="0 0 0"/>
      <geometry>
        <mesh filename="meshes/arm/visual/arm_link_el0.obj"/>
      </geometry>
    </visual>
    <!-- <collision>
      <geometry>
        <mesh filename="meshes/arm/collision/arm_link_el0.obj" />
      </geometry>
    </collision> -->
    <inertial>
      <origin xyz="0.04476621 -0.00271130 0.04991363"/>
      <inertia ixx="0.00175909" ixy="0.00006087" ixz="0.00092380" iyy="0.00269233" iyz="0.00005217" izz="0.00202854"/>
      <mass value="0.94831958"/>
    </inertial>
  </link>

  <joint name="arm_el0" type="revolute">
    <origin xyz="0.3385 0 0" rpy="0 0 0"/>
    <axis xyz="0 1 0"/>
    <parent link="arm_link_sh1"/>
    <child link="arm_link_el0"/>
    <limit effort="90.9" lower="0" upper="3.14159" velocity="100"/>
  </joint>

  <link name="arm_link_el1">
    <visual>
      <origin xyz="0 0 0" rpy="0 0 0"/>
      <geometry>
        <mesh filename="meshes/arm/visual/arm_link_el1.obj"/>
      </geometry>
    </visual>
    <!-- collision disabled for loco self-collision (arm is cuRobo-driven) -->
    <!-- <collision>
      <geometry>
        <mesh filename="meshes/arm/collision/arm_link_el1_main.obj" />
      </geometry>
    </collision> -->
    <!-- <collision>
      <geometry>
        <mesh filename="meshes/arm/collision/arm_link_el1_lip.obj" />
      </geometry>
    </collision> -->
    <inertial>
      <origin xyz="-0.16867073 -0.01616121 0.00001149"/>
      <inertia ixx="0.00117710" ixy="-0.00260549" ixz="0.00000156" iyy="0.01649389" iyz="-0.00000287" izz="0.01689901"/>
      <mass value="1.01754820"/>
    </inertial>
  </link>

  <joint name="arm_el1" type="revolute">
    <origin xyz="0.40330 0.0 0.0750" rpy="0 0 0"/>
    <axis xyz="1 0 0"/>
    <parent link="arm_link_el0"/>
    <child link="arm_link_el1"/>
    <limit effort="30.3" lower="-2.792530" upper="2.792530" velocity="100"/>
  </joint>

  <link name="arm_link_wr0">
    <visual>
      <origin xyz="0 0 0" rpy="0 0 0"/>
      <geometry>
        <mesh filename="meshes/arm/visual/arm_link_wr0.obj"/>
      </geometry>
    </visual>
    <!-- <collision>
      <geometry>
        <mesh filename="meshes/arm/collision/arm_link_wr0.obj" />
      </geometry>
    </collision> -->
    <inertial>
      <origin xyz="0.00952465 -0.01144406 0.00000186"/>
      <inertia ixx="0.00046738" ixy="0.00006957" ixz="0.00000040" iyy="0.00044968" iyz="0.00000016" izz="0.00053616"/>
      <mass value="0.58263740"/>
    </inertial>
  </link>

  <joint name="arm_wr0" type="revolute">
    <origin xyz="0.0 0.0 0.0" rpy="0 0 0"/>
    <axis xyz="0 1 0"/>
    <parent link="arm_link_el1"/>
    <child link="arm_link_wr0"/>
    <limit effort="30.3" lower="-1.8326" upper="1.8326" velocity="100"/>
  </joint>

  <link name="arm_link_wr1">
    <visual>
      <origin xyz="0 0 0" rpy="0 0 0"/>
      <geometry>
        <mesh filename="meshes/arm/visual/arm_link_wr1.obj"/>
      </geometry>
    </visual>
    <!-- collision disabled for loco self-collision (arm is cuRobo-driven) -->
    <!-- <collision>
      <geometry>
        <mesh filename="meshes/arm/collision/arm_link_wr1.obj" />
      </geometry>
    </collision> -->
    <inertial>
      <origin xyz="0.09751283 0.00009265 -0.01120523"/>
      <inertia ixx="0.00098836" ixy="-0.00000126" ixz="-0.00036919" iyy="0.00197018" iyz="-0.00000074" izz="0.00165791"/>
      <mass value="0.93335298"/>
    </inertial>
  </link>

  <joint name="arm_wr1" type="revolute">
    <origin xyz="0.0 0.0 0.0" rpy="0 0 0"/>
    <axis xyz="1 0 0"/>
    <parent link="arm_link_wr0"/>
    <child link="arm_link_wr1"/>
    <limit effort="30.3" lower="-2.87989" upper="2.87979" velocity="100"/>
  </joint>

  <!--Hand camera.-->
  <!-- <frame link="arm_link_wr1" name="hand_camera_body" rpy="0.0 1.41372 0.0" xyz="0.13495 0.0 0.00799"/>
  <frame link="arm_link_wr1" name="hand_color_sensor" rpy="-1.41372 0.0 -1.5708" xyz="0.13806 0.0202 0.02452"/>
  <frame link="arm_link_wr1" name="hand_depth_sensor" rpy="0.0 1.41372 0.0" xyz="0.13495 0.0 0.00799"/> -->

  <!-- ####################### Gripper ####################### -->

  <link name="arm_link_fngr">
    <visual>
      <origin xyz="0 0 0" rpy="0 0 0"/>
      <geometry>
        <mesh filename="meshes/gripper/visual/arm_link_fngr.obj"/>
      </geometry>
    </visual>
    <!-- <collision>
      <geometry>
        <mesh filename="meshes/gripper/collision/left_hinge.obj" />
      </geometry>
    </collision> -->
    <!-- gripper collision disabled for loco self-collision (arm is cuRobo-driven) -->
    <!-- <collision>
      <geometry>
        <mesh filename="meshes/gripper/collision/left_finger.obj" />
      </geometry>
    </collision>
    <collision>
      <geometry>
        <mesh filename="meshes/gripper/collision/left_tooth.obj" />
      </geometry>
    </collision> -->
    <!-- <collision>
      <geometry>
        <mesh filename="meshes/gripper/collision/right_hinge.obj" />
      </geometry>
    </collision> -->
    <!-- gripper collision disabled for loco self-collision (arm is cuRobo-driven) -->
    <!-- <collision>
      <geometry>
        <mesh filename="meshes/gripper/collision/right_finger.obj" />
      </geometry>
    </collision>
    <collision>
      <geometry>
        <mesh filename="meshes/gripper/collision/right_tooth.obj" />
      </geometry>
    </collision> -->
    <inertial>
      <origin xyz="0.03565178 0.00067200 -0.01227516"/>
      <inertia ixx="0.00025226" ixy="-0.00000536" ixz="-0.00015067" iyy="0.00048453" iyz="0.00000184" izz="0.00059145"/>
      <mass value="0.22383315"/>
    </inertial>
  </link>

  <joint name="arm_f1x" type="revolute">
    <origin xyz="0.11745 0.0 0.014820" rpy="0 0 0"/>
    <axis xyz="0.0 1.0 0.0"/>
    <parent link="arm_link_wr1"/>
    <child link="arm_link_fngr"/>
    <limit effort="15.32" lower="-1.5708" upper="0.0" velocity="100"/>
  </joint>

  <link name="arm_link_jaw">
    <inertial>
      <origin xyz="0 0 0"/>
      <mass value="0.05"/>
      <inertia ixx="1e-4" ixy="0" ixz="0" iyy="1e-4" iyz="0" izz="1e-4"/>
    </inertial>
    <!-- jaw collision disabled for loco self-collision (arm is cuRobo-driven) -->
    <!-- <collision>
      <geometry>
        <mesh filename="meshes/gripper/collision/front_jaw.obj" />
      </geometry>
    </collision>
    <collision>
      <geometry>
        <mesh filename="meshes/gripper/collision/middle_jaw.obj" />
       </geometry>
    </collision>
    <collision>
      <geometry>
        <mesh filename="meshes/gripper/collision/jaw_tooth.obj" />
       </geometry>
    </collision> -->
  </link>

  <joint name="arm_jaw" type="fixed">
    <parent link="arm_link_wr1"/>
    <child link="arm_link_jaw"/>
  </joint>

</robot>
